<?xml version="1.0" encoding="UTF-8"?>
<!-- Generated by org.testng.reporters.JUnitReportReporter -->
<testsuite hostname="Sanjay" failures="1" tests="10" name="runner.TestngTestRunner" time="49.669" errors="0" timestamp="2023-12-20T20:00:34 CET" skipped="0">
  <testcase classname="runner.TestngTestRunner" name="runScenario" time="8.413"/>
  <testcase classname="runner.TestngTestRunner" name="runScenario" time="2.369"/>
  <testcase classname="runner.TestngTestRunner" name="runScenario" time="2.800">
    <failure message="did not expect [2] but found [2]" type="java.lang.AssertionError">
      <![CDATA[java.lang.AssertionError: did not expect [2] but found [2]
at org.testng.Assert.fail(Assert.java:111)
at org.testng.Assert.failEquals(Assert.java:1582)
at org.testng.Assert.assertNotEqualsImpl(Assert.java:157)
at org.testng.Assert.assertNotEquals(Assert.java:2198)
at org.testng.Assert.assertNotEquals(Assert.java:2220)
at stepDefinitions.ToDoHomePageStepDefinition.duplicateTasks(ToDoHomePageStepDefinition.java:112)
at âœ½.Check if 2 Duplicate tasks are added(file:///C:/Users/vigne/Desktop/WoltersKluwers/ToDo/src/test/java/features/NegativeScenarios.feature:10)
]]>
    </failure>
  </testcase> <!-- runScenario -->
  <testcase classname="runner.TestngTestRunner" name="runScenario" time="2.621"/>
  <testcase classname="runner.TestngTestRunner" name="runScenario" time="12.519"/>
  <testcase classname="runner.TestngTestRunner" name="runScenario" time="2.145"/>
  <testcase classname="runner.TestngTestRunner" name="runScenario" time="6.565"/>
  <testcase classname="runner.TestngTestRunner" name="runScenario" time="1.929"/>
  <testcase classname="runner.TestngTestRunner" name="runScenario" time="2.117"/>
  <testcase classname="runner.TestngTestRunner" name="runScenario" time="8.191"/>
</testsuite> <!-- runner.TestngTestRunner -->
